Workbook
Name Podróżni: 'Dane 2'!$A$1:$E$82

Sheet Dane 1
A1: Oddelegowanie | B1: Dieta | C1: Biety + noclegi | D1: Ubezpieczenie | E1: Dopłata za nadbagaż
A2: Chorwacja | B2: 2800 | C2: 4490 | D2: 65.25 | E2: 325
A3: Hiszpania | B3: 2800 | C3: 7918 | D3: 65.25 | E3: 325
A4: Włochy | B4: 4200 | C4: 8697 | D4: 91.25 | E4: 325
A5: Turcja | B5: 4200 | C5: 7470 | D5: 91.25 | E5: 650
A6: Grecja | B6: 4200 | C6: 8079 | D6: 91.25 | E6: 325
A7: Austria | B7: 3600 | C7: 6500 | D7: 34.8 | E7: 325

Sheet Dane 2
A1: Imię | B1: Nazwisko | C1: Oddział firmy | D1: Płeć | E1: Wiek | F1: Data wylotu | G1: Data przylotu | H1: Liczba dni | I1: Oddelegowanie | J1: Koszt [bilety+noclegi] | K1: Dieta | L1: Dodatkowe ubezp. | M1: Nadbagaż [szt] | N1: Dopłata za nadbagaż | O1: Kosz całkowity
A2: Adam | B2: Piotrowicz | C2: Warszawa | D2: M | E2: 55 | F2: ='A1'!XFC2 -> 44119 | G2: =F2+H2 -> 44133 | H2: 14 | I2: Chorwacja | J2: 4490 | K2: 2800 | L2: 65.25 | M2: 1 | N2: 325 | O2: =J2+K2+L2+N2 -> 7680.25
A3: Adam | B3: Czyżuk | C3: Warszawa | D3: M | E3: 24 | F3: ='A1'!XFC3 -> 44149 | G3: =F3+H3 -> 44163 | H3: 14 | I3: Hiszpania | J3: 7918 | K3: 2800 | L3: 65.25 | N3: 0 | O3: =J3+K3+L3+N3 -> 10783.25
A4: Adrianna | B4: Kulik | C4: Poznań | D4: K | E4: 44 | F4: ='A1'!XFC4 -> 44147 | G4: =F4+H4 -> 44157 | H4: 10 | I4: Hiszpania | J4: 6084 | K4: 2000 | L4: 65.25 | N4: 0 | O4: =J4+K4+L4+N4 -> 8149.25
A5: Adrianna | B5: Mikołajewska | C5: Poznań | D5: K | E5: 39 | F5: ='A1'!XFC5 -> 44121 | G5: =F5+H5 -> 44142 | H5: 21 | I5: Włochy | J5: 8697 | K5: 4200 | L5: 91.25 | N5: 0 | O5: =J5+K5+L5+N5 -> 12988.25
A6: Agnieszka | B6: Zawora | C6: Kraków | D6: K | E6: 32 | F6: ='A1'!XFC6 -> 44116 | G6: =F6+H6 -> 44137 | H6: 21 | I6: Turcja | J6: 7470 | K6: 4200 | L6: 91.25 | M6: 2 | N6: 650 | O6: =J6+K6+L6+N6 -> 12411.25
A7: Agnieszka | B7: Pietrzak | C7: Kraków | D7: K | E7: 47 | F7: ='A1'!XFC7 -> 44172 | G7: =F7+H7 -> 44193 | H7: 21 | I7: Grecja | J7: 8079 | K7: 4200 | L7: 91.25 | M7: 1 | N7: 325 | O7: =J7+K7+L7+N7 -> 12695.25
A8: Andrzej | B8: Robek | C8: Kraków | D8: M | E8: 33 | F8: ='A1'!XFC8 -> 44182 | G8: =F8+H8 -> 44189 | H8: 7 | I8: Turcja | J8: 3490 | K8: 1400 | L8: 34.8 | M8: 1 | N8: 325 | O8: =J8+K8+L8+N8 -> 5249.8
A9: Andrzej | B9: Jadziak | C9: Warszawa | D9: M | E9: 38 | F9: ='A1'!XFC9 -> 44132 | G9: =F9+H9 -> 44147 | H9: 15 | I9: Hiszpania | J9: 8376 | K9: 3000 | L9: 91.25 | M9: 1 | N9: 325 | O9: =J9+K9+L9+N9 -> 11792.25
A10: Andrzej | B10: Twarnowski | C10: Kraków | D10: M | E10: 49 | F10: ='A1'!XFC10 -> 44180 | G10: =F10+H10 -> 44187 | H10: 7 | I10: Włochy | J10: 3899 | K10: 1400 | L10: 34.8 | N10: 0 | O10: =J10+K10+L10+N10 -> 5333.8
A11: Anna | B11: Kacprzak | C11: Poznań | D11: K | E11: 29 | F11: ='A1'!XFC11 -> 44181 | G11: =F11+H11 -> 44202 | H11: 21 | I11: Włochy | J11: 8697 | K11: 4200 | L11: 91.25 | M11: 1 | N11: 325 | O11: =J11+K11+L11+N11 -> 13313.25
A12: Anna | B12: Piechocka | C12: Warszawa | D12: K | E12: 52 | F12: ='A1'!XFC12 -> 44187 | G12: =F12+H12 -> 44208 | H12: 21 | I12: Chorwacja | J12: 5985 | K12: 4200 | L12: 91.25 | M12: 1 | N12: 325 | O12: =J12+K12+L12+N12 -> 10601.25
A13: Anna | B13: Piechocka | C13: Poznań | D13: K | E13: 32 | F13: ='A1'!XFC13 -> 44180 | G13: =F13+H13 -> 44194 | H13: 14 | I13: Hiszpania | J13: 7918 | K13: 2800 | L13: 65.25 | N13: 0 | O13: =J13+K13+L13+N13 -> 10783.25
A14: Barbara | B14: Fornal | C14: Warszawa | D14: K | E14: 55 | F14: ='A1'!XFC14 -> 44175 | G14: =F14+H14 -> 44189 | H14: 14 | I14: Chorwacja | J14: 4490 | K14: 2800 | L14: 65.25 | N14: 0 | O14: =J14+K14+L14+N14 -> 7355.25
A15: Barbara | B15: Jelikowska | C15: Warszawa | D15: K | E15: 24 | F15: ='A1'!XFC15 -> 44125 | G15: =F15+H15 -> 44139 | H15: 14 | I15: Chorwacja | J15: 4490 | K15: 2800 | L15: 65.25 | M15: 1 | N15: 325 | O15: =J15+K15+L15+N15 -> 7680.25
A16: Barbara | B16: Griczan | C16: Warszawa | D16: K | E16: 36 | F16: ='A1'!XFC16 -> 44112 | G16: =F16+H16 -> 44126 | H16: 14 | I16: Turcja | J16: 5480 | K16: 2800 | L16: 65.25 | N16: 0 | O16: =J16+K16+L16+N16 -> 8345.25
A17: Barbara | B17: Gruda | C17: Poznań | D17: K | E17: 45 | F17: ='A1'!XFC17 -> 44175 | G17: =F17+H17 -> 44189 | H17: 14 | I17: Hiszpania | J17: 7918 | K17: 2800 | L17: 65.25 | N17: 0 | O17: =J17+K17+L17+N17 -> 10783.25
A18: Barbara | B18: Mączyńska | C18: Kraków | D18: K | E18: 26 | F18: ='A1'!XFC18 -> 44130 | G18: =F18+H18 -> 44144 | H18: 14 | I18: Hiszpania | J18: 7918 | K18: 2800 | L18: 65.25 | M18: 1 | N18: 325 | O18: =J18+K18+L18+N18 -> 11108.25
A19: Barbara | B19: Sadurski | C19: Poznań | D19: K | E19: 37 | F19: ='A1'!XFC19 -> 44117 | G19: =F19+H19 -> 44131 | H19: 14 | I19: Hiszpania | J19: 7918 | K19: 2800 | L19: 65.25 | M19: 1 | N19: 325 | O19: =J19+K19+L19+N19 -> 11108.25
A20: Barbara | B20: Kiszewska | C20: Warszawa | D20: K | E20: 39 | F20: ='A1'!XFC20 -> 44173 | G20: =F20+H20 -> 44187 | H20: 14 | I20: Włochy | J20: 6298 | K20: 2800 | L20: 65.25 | N20: 0 | O20: =J20+K20+L20+N20 -> 9163.25
A21: Barbara | B21: Jagiel | C21: Poznań | D21: K | E21: 54 | F21: ='A1'!XFC21 -> 44169 | G21: =F21+H21 -> 44183 | H21: 14 | I21: Hiszpania | J21: 7918 | K21: 2800 | L21: 65.25 | N21: 0 | O21: =J21+K21+L21+N21 -> 10783.25
A22: Elwira | B22: Policzawska | C22: Kraków | D22: K | E22: 50 | F22: ='A1'!XFC22 -> 44116 | G22: =F22+H22 -> 44130 | H22: 14 | I22: Hiszpania | J22: 7918 | K22: 2800 | L22: 65.25 | N22: 0 | O22: =J22+K22+L22+N22 -> 10783.25
A23: Ewa | B23: Niemota | C23: Poznań | D23: K | E23: 37 | F23: ='A1'!XFC23 -> 44189 | G23: =F23+H23 -> 44203 | H23: 14 | I23: Chorwacja | J23: 4490 | K23: 2800 | L23: 65.25 | N23: 0 | O23: =J23+K23+L23+N23 -> 7355.25
A24: Ewa | B24: Mikołajczuk | C24: Warszawa | D24: K | E24: 34 | F24: ='A1'!XFC24 -> 44131 | G24: =F24+H24 -> 44152 | H24: 21 | I24: Turcja | J24: 7470 | K24: 4200 | L24: 91.25 | M24: 1 | N24: 325 | O24: =J24+K24+L24+N24 -> 12086.25
A25: Ewa | B25: Masztaler | C25: Kraków | D25: K | E25: 39 | F25: ='A1'!XFC25 -> 44170 | G25: =F25+H25 -> 44184 | H25: 14 | I25: Włochy | J25: 6298 | K25: 2800 | L25: 65.25 | M25: 1 | N25: 325 | O25: =J25+K25+L25+N25 -> 9488.25
A26: Ewa | B26: Szumińska | C26: Warszawa | D26: K | E26: 37 | F26: ='A1'!XFC26 -> 44142 | G26: =F26+H26 -> 44163 | H26: 21 | I26: Grecja | J26: 8079 | K26: 4200 | L26: 91.25 | M26: 1 | N26: 325 | O26: =J26+K26+L26+N26 -> 12695.25
A27: Ewelina | B27: Sztycer | C27: Warszawa | D27: K | E27: 33 | F27: ='A1'!XFC27 -> 44113 | G27: =F27+H27 -> 44134 | H27: 21 | I27: Turcja | J27: 7470 | K27: 4200 | L27: 91.25 | M27: 2 | N27: 650 | O27: =J27+K27+L27+N27 -> 12411.25
A28: Ewelina | B28: Kowalska | C28: Poznań | D28: K | E28: 42 | F28: ='A1'!XFC28 -> 44121 | G28: =F28+H28 -> 44142 | H28: 21 | I28: Turcja | J28: 7470 | K28: 4200 | L28: 91.25 | N28: 0 | O28: =J28+K28+L28+N28 -> 11761.25
A29: Franciszek | B29: Lindarek | C29: Kraków | D29: M | E29: 25 | F29: ='A1'!XFC29 -> 44165 | G29: =F29+H29 -> 44175 | H29: 10 | I29: Włochy | J29: 4927 | K29: 2000 | L29: 65.25 | N29: 0 | O29: =J29+K29+L29+N29 -> 6992.25
A30: Jadwiga | B30: Milecka | C30: Poznań | D30: K | E30: 28 | F30: ='A1'!XFC30 -> 44171 | G30: =F30+H30 -> 44185 | H30: 14 | I30: Chorwacja | J30: 4490 | K30: 2800 | L30: 65.25 | N30: 0 | O30: =J30+K30+L30+N30 -> 7355.25
A31: Jadwiga | B31: Gilecka | C31: Poznań | D31: K | E31: 53 | F31: ='A1'!XFC31 -> 44189 | G31: =F31+H31 -> 44203 | H31: 14 | I31: Turcja | J31: 5480 | K31: 2800 | L31: 65.25 | N31: 0 | O31: =J31+K31+L31+N31 -> 8345.25
A32: Jadwiga | B32: Jolecka | C32: Warszawa | D32: K | E32: 20 | F32: ='A1'!XFC32 -> 44108 | G32: =F32+H32 -> 44122 | H32: 14 | I32: Chorwacja | J32: 4490 | K32: 2800 | L32: 65.25 | N32: 0 | O32: =J32+K32+L32+N32 -> 7355.25
A33: Jadwiga | B33: Fulecka | C33: Warszawa | D33: K | E33: 47 | F33: ='A1'!XFC33 -> 44176 | G33: =F33+H33 -> 44190 | H33: 14 | I33: Hiszpania | J33: 7918 | K33: 2800 | L33: 65.25 | N33: 0 | O33: =J33+K33+L33+N33 -> 10783.25
A34: Jakub | B34: Kowalski | C34: Kraków | D34: M | E34: 40 | F34: ='A1'!XFC34 -> 44188 | G34: =F34+H34 -> 44202 | H34: 14 | I34: Chorwacja | J34: 4490 | K34: 2800 | L34: 65.25 | N34: 0 | O34: =J34+K34+L34+N34 -> 7355.25
A35: Jakub | B35: Więcławski | C35: Poznań | D35: M | E35: 22 | F35: ='A1'!XFC35 -> 44141 | G35: =F35+H35 -> 44155 | H35: 14 | I35: Grecja | J35: 5886 | K35: 2800 | L35: 65.25 | N35: 0 | O35: =J35+K35+L35+N35 -> 8751.25
A36: Jan | B36: Tomczak | C36: Poznań | D36: M | E36: 46 | F36: ='A1'!XFC36 -> 44189 | G36: =F36+H36 -> 44203 | H36: 14 | I36: Hiszpania | J36: 7918 | K36: 2800 | L36: 65.25 | N36: 0 | O36: =J36+K36+L36+N36 -> 10783.25
A37: Jan | B37: Piórkowski | C37: Warszawa | D37: M | E37: 22 | F37: ='A1'!XFC37 -> 44131 | G37: =F37+H37 -> 44145 | H37: 14 | I37: Chorwacja | J37: 4490 | K37: 2800 | L37: 65.25 | M37: 1 | N37: 325 | O37: =J37+K37+L37+N37 -> 7680.25
A38: Janusz | B38: Kurant | C38: Warszawa | D38: M | E38: 49 | F38: ='A1'!XFC38 -> 44170 | G38: =F38+H38 -> 44185 | H38: 15 | I38: Włochy | J38: 6641 | K38: 3000 | L38: 91.25 | N38: 0 | O38: =J38+K38+L38+N38 -> 9732.25
A39: Jarosław | B39: Kukiel | C39: Kraków | D39: M | E39: 25 | F39: ='A1'!XFC39 -> 44127 | G39: =F39+H39 -> 44141 | H39: 14 | I39: Chorwacja | J39: 4490 | K39: 2800 | L39: 65.25 | N39: 0 | O39: =J39+K39+L39+N39 -> 7355.25
A40: Jarosław | B40: Kujawa | C40: Poznań | D40: M | E40: 37 | F40: ='A1'!XFC40 -> 44161 | G40: =F40+H40 -> 44175 | H40: 14 | I40: Grecja | J40: 5886 | K40: 2800 | L40: 65.25 | N40: 0 | O40: =J40+K40+L40+N40 -> 8751.25
...

Sheet A1
XFC1: Data wylotu
XFC2: 44119
XFC3: 44149
XFC4: 44147
XFC5: 44121
XFC6: 44116
XFC7: 44172
XFC8: 44182
XFC9: 44132
XFC10: 44180
XFC11: 44181
XFC12: 44187
XFC13: 44180
... XFC132: 44162
